<?xml version="1.0"?>

<robot name="myrobot" xmlns:xacro="http://www.ros.org/wiki/xacro">

      <xacro:property name="camera_size" value="0.05" />
      <xacro:property name="camera_mass" value="0.1" />
     <xacro:include filename="$(find spcbot_description)/urdf/materials.xacro"/>
     <xacro:include filename="$(find spcbot_description)/urdf/spcbot.gazebo"/>

     <link name="chassis">
        <pose>0 0 0.1 0 0 0</pose>
        <inertial>
          <origin xyz="0.0 0.0 0.1" rpy="0.0 0.0 0.0"/>
          <mass value="15.0"/>
          <inertia ixx="0.1" ixy="0.0" ixz="0.0" iyy="0.1" iyz="0.0" izz="0.1"/>
        </inertial>
        <visual name="chassis_visual">
           <origin xyz="0.0 0.0 0.0" rpy="0.0 0.0 0.0"/>
           <geometry>
              <box size = "0.4 0.2 0.1"/>
           </geometry>
        </visual>
        <collision name="collision">
            <geometry>
                <box size="0.4 0.2 0.1"/>
            </geometry>
        </collision>

        <collision name="caster_collision">
        <origin xyz="-0.15 0 -0.05" rpy="0.0 0.0 0.0"/>
           <geometry>
              <sphere radius= "0.05"/>
           </geometry>
           <surface>
             <friction>
               <ode>
                  <mu>0</mu>
                  <mu2>0</mu2>
                  <slip1>1.0</slip1>
                  <slip2>1.0</slip2>
               </ode>
             </friction>
           </surface>
         </collision>

       <visual name='caster_visual'>
	       <origin xyz="0.15 0 -0.05" rpy="0.0 0.0 0.0"/>
	       <geometry>
		  <sphere radius="0.05"/>
	       </geometry>
               <metarial name="blue">
                  <color rgba="${70/255} ${229/255} ${221/255} 1.0"/>
               </metarial>
       </visual>


       <collision name="caster_front_collision">
       <origin xyz="0.15 0 -0.05" rpy="0.0 0.0 0.0"/>
           <geometry>
              <sphere radius= "0.05"/>
           </geometry>
           <surface>
             <friction>
               <ode>
                  <mu>0</mu>
                  <mu2>0</mu2>
                  <slip1>1.0</slip1>
                  <slip2>1.0</slip2>
               </ode>
             </friction>
           </surface>
         </collision>
   

       <visual name='caster_front_visual'>
	       <origin xyz="0.15 0 -0.05" rpy="0.0 0.0 0.0"/>
	       <geometry>
		  <sphere radius="0.05"/>
	       </geometry>
       </visual>

     </link>

    <link name="left_wheel">
<!--origin xyz="0.1 0.13 0.1 rpy=0 1.5707 1.5707"/-->
    <collision name="collision_left">
        <origin xyz="0 0 0" rpy="0 1.5707 1.5707"/>
        <geometry>
           <cylinder radius="0.1" length="0.05"/>
        </geometry>
    </collision>
    <visual name="left_wheel_visual">
       <origin xyz="0 0 0" rpy="0 1.5707 1.5707"/>
        <geometry>
           <cylinder radius="0.1" length="0.05"/>
        </geometry>
        <metarial name="PBlack">
        </metarial>

   </visual>

   <inertial>
        <origin xyz="0 0 0" rpy="0 1.5707 1.5707"/>
        <mass value="5"/>
        <inertia
             ixx=".1" ixy="0.0" ixz="0.0"
             iyy=".1" iyz="0.0" izz="0.1"/>
   </inertial>
   </link>

   <link name="right_wheel">
   <!--origin xyz="0.1 -0.13 0.1" rpy="0 1.5707 1.5707"/-->
   <collision name="collision_right">
        <origin xyz="0 0 0" rpy="0 1.5707 1.5707"/>
        <geometry>
          <cylinder radius="0.1" length="0.05"/>
        </geometry>
   </collision>

   <visual name="left_wheel_visual">
       <origin xyz="0 0 0" rpy="0 1.5707 1.5707"/>
        <geometry>
           <cylinder radius="0.1" length="0.05"/>
        </geometry>
       <metarial name="PBlack">
        </metarial>
   </visual>
   <inertial>
        <origin xyz="0 0 0" rpy="0 1.5707 1.5707"/>
        <mass value="5"/>
        <inertia
             ixx=".1" ixy="0.0" ixz="0.0"
             iyy=".1" iyz="0.0" izz="0.1"/>
   </inertial>
   </link>

   <joint type="continuous" name="left_wheel_hinge">
	   <!--origin xyz="0.1 0.13 0" rpy="0 1.5707 1.5707"/-->
	   <origin xyz= "0 0.15 0" rpy="0 0 0"/>
	   <child link="left_wheel"/>
	   <parent link="chassis"/>
	   <axis xyz="0 1 0" rpy="0 0 0"/>
	   <limit effort="10000" velocity="1000"/>
	   <joint_properties damping="1.0" friction="1.0"/>
   </joint>

   <joint type="continuous" name="right_wheel_hinge">
	   <!--origin xyz="0.1 -0.13 0" rpy="0 1.5707 1.5707"/-->
	   <origin xyz= "0 -0.15 0" rpy="0 0 0"/>
	   <child link="right_wheel"/>
	   <parent link="chassis"/>
	   <axis xyz="0 1 0" rpy="0 0 0"/>
	   <limit effort="10000" velocity="1000"/>
	   <joint_properties damping="1.0" friction="1.0"/>
   </joint>

<link name="back_wheel">
<!--origin xyz="0.1 0.13 0.1 rpy=0 1.5707 1.5707"/-->
    <collision name="collision_back">
        <origin xyz="0 0 0" rpy="0 1.5707 1.5707"/>
        <geometry>
           <cylinder radius="0.1" length="0.05"/>
        </geometry>
    </collision>
    <visual name="back_wheel_visual">
       <origin xyz="0 0 0" rpy="0 1.5707 1.5707"/>
        <geometry>
           <cylinder radius="0.1" length="0.05"/>
        </geometry>
        <metarial name="PBlack">
        </metarial>

   </visual>

   <inertial>
        <origin xyz="0 0 0" rpy="0 1.5707 1.5707"/>
        <mass value="5"/>
        <inertia
             ixx=".1" ixy="0.0" ixz="0.0"
             iyy=".1" iyz="0.0" izz="0.1"/>
   </inertial>
   </link>  

   <joint type="continuous" name="back_wheel_hinge">
	   <!--origin xyz="0.1 -0.13 0" rpy="0 1.5707 1.5707"/-->
	   <origin xyz= "-0.1 0 0" rpy="0 0 0"/>
	   <child link="back_wheel"/>
	   <parent link="chassis"/>
	   <axis xyz="0 1 0" rpy="0 0 0"/>
	   <limit effort="10000" velocity="1000"/>
	   <joint_properties damping="1.0" friction="1.0"/>
   </joint>


  <!-- Camera -->
  <link name="camera">
    <collision>
      <origin xyz="0 0 0" rpy="0 0 0"/>
      <geometry>
    <box size="${camera_size} ${camera_size} ${camera_size}"/>
      </geometry>
    </collision>

    <visual>
      <origin xyz="0 0 0" rpy="0 0 0"/>
      <geometry>
    <box size="${camera_size} ${camera_size} ${camera_size}"/>
      </geometry>
      <material name="red"/>
    </visual>

    <inertial>
      <mass value="${camera_mass}" />
      <origin xyz="0 0 0" rpy="0 0 0"/>
      <inertia ixx="1e-6" ixy="0" ixz="0" iyy="1e-6" iyz="0" izz="1e-6" />
    </inertial>
  </link>  


    <joint name="camera_joint" type="fixed">
    <axis xyz="0 1 0" />
    <origin xyz=".2 0 0" rpy="0 0 0"/>
    <parent link="chassis"/>
    <child link="camera"/>
  </joint>


</robot>
